<?xml version="1.0" ?>
<!-- 
  This is not a standalone urdf for kobuki. It simply defines the 'kobuki' tag that can
  be incorporated by other urdf files (e.g. turtlebot).
  
  See kobuki_standalone.urdf.xacro for a standalone urdf to be tested with
      kobuki_description/launch/view_model.launch
 -->

<robot name="adam" xmlns:xacro="http://ros.org/wiki/xacro">
 
  <!--==================== Refer to files has some properties ==================== --> 

  <xacro:include filename="$(find adam_description)/urdf/common_properties.urdf.xacro"/>
  <xacro:include filename="$(find adam_description)/urdf/adam_base_gazebo.urdf.xacro"/>

  <!-- adam URDF for Gazebo --> 
  <!--==================== adam Base and its reletion to the ground ==================== --> 
  <xacro:macro name="kobuki">   
    <link name="base_footprint"/>

    <joint name="base_joint" type="fixed">
      <origin xyz="0 0 0.0102" rpy="0 0 ${-M_PI/2}" /> <!--${-M_PI/2}-->
      <parent link="base_footprint"/>
      <child link="base_link" />
    </joint>
    <link name="base_link">
      <visual>
        <origin xyz="0.001 0 0.001" rpy="0 0 ${M_PI}"/>
        <geometry>
          <mesh
            filename="package://adam_description/meshes/base_link.STL" />
        </geometry>
        <material name="material_grey_blue" />

          <!--color
            rgba="0.79216 0.81961 0.93333 1" />
        </material-->
      </visual>
      <collision>
        <geometry>
          <cylinder length="0.0010938" radius="0.00178"/>
          <!--mesh filename="package://adam_description/meshes/base_link.STL" /-->
        </geometry>
        <origin xyz="-1.33382025877251E-05 0 -0.0137208025556793" rpy="0 0 ${M_PI}"/>
      </collision>
      <inertial>
        <origin
          xyz="0 0 0"
          rpy="0 0 0" />
        <mass value="2.4" />
        <origin xyz="0 0 0" />
        <inertia ixx="0.001" ixy="0.0" ixz="0.0"
                 iyy="0.001" iyz="0.0" 
                 izz="0.001" />
        <!--
        <mass
          value="6.28688291799272" />
        <inertia ixx="0.36019564010307"
        ixy="-0.000630349878810838"
        ixz="1.31933307928162E-05"
        iyy="0.027719129041023"
        iyz="0.00832426388228602"
        izz="0.372972029310331" />
        -->
      </inertial>
    </link>
    
    <!-- we fake Left and Right wheels for the robot to move correctly according to the 
         controller we use kobuki -->

    <!-- #######*********################### S T A R T ###############*******###################-->


    <!-- ##############################FAKE Left wheel##############################-->

    <joint name="wheel_left_joint" type="continuous">
      <origin xyz="0.1817 -0.0159043125 0.032" rpy="-1.5708 -1.179 -1.5708" />
      <parent link="base_link"/>
      <child link="adam_wheel_left_link"/>
      <axis xyz="0 0 -1"/>
    </joint>
    <link name="adam_wheel_left_link">
      <collision>
       <origin xyz="-4.2891E-06 2.8551E-06 0.028055" rpy="0 0 0" />
         <geometry>
           <cylinder length="0.03" radius="0.065"/>
           <!--mesh filename="package://adam_description/meshes/wheelleft.STL" /-->
         </geometry>
      </collision>
      
      <inertial>
       <origin
        xyz="-4.2885E-06 2.8578E-06 0.028055"
        rpy="0 0 0" />
       <mass value="0.01" />
        <origin xyz="0 0 0" />
        <inertia ixx="0.001" ixy="0.0" ixz="0.0"
                 iyy="0.001" iyz="0.0" 
                 izz="0.001" />
      </inertial>
    </link>

    <!-- ##############################FAKE Right wheel#############################-->

    <joint name="wheel_right_joint" type="continuous">
      <origin xyz="-0.1817 -0.0159043125 0.032" rpy="-1.5708 1.179 1.5708" />
      <parent link="base_link"/>
      <child link="adam_wheel_right_link"/>
      <axis xyz="0 0 1"/>
    </joint>
    <link name="adam_wheel_right_link">
      <collision>
       <origin xyz="4.2974E-06 2.8581E-06 0.028055" rpy="0 0 0" />
         <geometry>
           <cylinder length="0.03" radius="0.065"/>
           <!--mesh filename="package://adam_description/meshes/wheelright.STL" /-->
         </geometry>
      </collision>

      <inertial>
       <origin
         xyz="4.2974E-06 2.8581E-06 0.028055"
         rpy="0 0 0" />
        <mass value="0.01" />
        <origin xyz="0 0 0" />
        <inertia ixx="0.001" ixy="0.0" ixz="0.0"
                 iyy="0.001" iyz="0.0" 
                 izz="0.001" />
     </inertial>
    </link>
  
    <!-- ##############*********############### E N D #################*******################### -->

  
    <!-- ==================== Left Side wheels and its joint ====================-->
  
    <!-- ======= Left side [front] wheel and its joint ========-->
    <joint name="wheel_leftfront_joint" type="fixed">
      <origin xyz="0.1817 -0.084823 0.032" rpy="-1.5708 -1.179 -1.5708" />
      <parent link="base_link"/>
      <child link="adam_wheel_leftfront_link"/>
      <axis xyz="0 0 1"/>
    </joint>
    <link name="adam_wheel_leftfront_link">

      <collision>s
       <origin xyz="-4.2891E-06 2.8551E-06 0.028055" rpy="0 0 0" />
         <geometry>
           <cylinder length="0.03" radius="0.065"/>
           <!--mesh filename="package://adam_description/meshes/wheelleft.STL" /-->
         </geometry>
      </collision>
      
      <inertial>
       <origin
        xyz="-4.2885E-06 2.8578E-06 0.028055"
        rpy="0 0 0" />
       <mass value="0.01" />
        <origin xyz="0 0 0" />
        <inertia ixx="0.001" ixy="0.0" ixz="0.0"
                 iyy="0.001" iyz="0.0" 
                 izz="0.001" />
       <!--
       <mass
        value="0.28581" />
          <inertia ixx="2.551E-06"
        ixy="8.984E-11"
        ixz="-1.2287E-08"
        iyy="2.5511E-06"
        iyz="8.1632E-09"
        izz="8.0255E-09" />
        -->
      </inertial>

      <visual>
        <geometry>
          <mesh filename="package://adam_description/meshes/wheelleft.STL"/>
        </geometry>
        <material
          name="rubber">
          <color
          rgba="0.79216 0.81961 0.93333 1" />
        </material>      
        <origin xyz="0 0 0" rpy="0 0 0"/>
      </visual>

    </link>

<!-- ======= Left side [back] wheel and its joint ========-->
    <joint name="wheel_leftback_joint" type="fixed">
      <origin xyz="0.1817 0.084823 0.032" rpy="-1.5708 1.2262 -1.5708" />
      <parent link="base_link"/>
      <child link="adam_wheel_leftback_link"/>
      <axis xyz="0 0 1"/>
    </joint>
    <link name="adam_wheel_leftback_link">
      <collision>
       <origin
        xyz="-4.2885E-06 2.8578E-06 0.028055"
        rpy="0 0 0" />
         <geometry>
          <cylinder length="0.03" radius="0.065"/>
           <!--mesh filename="package://adam_description/meshes/wheelleft.STL" /-->
         </geometry>
      </collision>
      
      <inertial>
       <origin
        xyz="-4.2885E-06 2.8578E-06 0.028055"
        rpy="0 0 0" />
        <mass value="0.01" />
        <origin xyz="0 0 0" />
        <inertia ixx="0.001" ixy="0.0" ixz="0.0"
                 iyy="0.001" iyz="0.0" 
                 izz="0.001" />
       <!--
       <mass
        value="0.28581" />
          <inertia ixx="2.5513E-06"
        ixy="8.9916E-11"
        ixz="-1.2287E-08"
        iyy="2.5514E-06"
        iyz="8.1712E-09"
        izz="8.0256E-09"/>
      -->

      </inertial>

      <visual>
        <geometry>
          <mesh filename="package://adam_description/meshes/wheelleft.STL"/>
        </geometry>
        <material
          name="rubber">
          <color
          rgba="0.79216 0.81961 0.93333 1" />
        </material>      
        <origin xyz="0 0 0" rpy="0 0 0"/>
      </visual>

    </link>


   <!-- ==================== Right side wheels and its joints ====================-->   

   <!-- ======= Right side [front] wheel and its joint ========--> 
    <joint name="wheel_rightfront_joint" type="fixed">
      <origin xyz="-0.1817 -0.084823 0.032" rpy="-1.5708 1.179 1.5708" />
      <parent link="base_link"/>
      <child link="adam_wheel_rightfront_link"/>
      <axis xyz="0 0 1"/>
    </joint>
    <link name="adam_wheel_rightfront_link">
      <collision>
       <origin xyz="4.2974E-06 2.8581E-06 0.028055" rpy="0 0 0" />
         <geometry>
           <cylinder length="0.03" radius="0.065"/>
           <!--mesh filename="package://adam_description/meshes/wheelright.STL" /-->
         </geometry>
      </collision>

      <inertial>
       <origin
         xyz="4.2974E-06 2.8581E-06 0.028055"
         rpy="0 0 0" />
        <mass value="0.01" />
        <origin xyz="0 0 0" />
        <inertia ixx="0.001" ixy="0.0" ixz="0.0"
                 iyy="0.001" iyz="0.0" 
                 izz="0.001" />
       <!--
       <mass
         value="0.28581" />
           <inertia ixx="2.5515E-06"
        ixy="9.0113E-11"
        ixz="-1.2313E-08"
        iyy="2.5516E-06"
        iyz="8.1732E-09"
        izz="8.0261E-09" />
      -->

     </inertial>

      <visual>
        <geometry>
          <mesh filename="package://adam_description/meshes/wheelright.STL"/>
        </geometry>
        <material
          name="rubber">
          <color
          rgba="0.79216 0.81961 0.93333 1" />
        </material>      
        <origin xyz="0 0 0" rpy="0 0 0"/>
      </visual>

    </link>

<!-- ======= Right side [back] wheel and its joint ========--> 
    <joint name="wheel_rightback_joint" type="fixed">
      <origin xyz="-0.1817 0.084823 0.032" rpy="1.5708 -0.23913 -1.5708" />
      <parent link="base_link"/>
      <child link="adam_wheel_rightback_link"/>
      <axis xyz="0 0 1"/>
    </joint>
    <link name="adam_wheel_rightback_link">
      <collision>
       <origin
        xyz="-4.2905E-06 2.8574E-06 0.028055"
        rpy="0 0 0" />
         <geometry>
          <cylinder length="0.03" radius="0.065"/>
           <!--mesh filename="package://adam_description/meshes/wheelright.STL" /-->
         </geometry>
      </collision>

      <inertial>
       <origin
         xyz="-4.2905E-06 2.8574E-06 0.028055"
         rpy="0 0 0" />
       <mass value="0.01" />
        <origin xyz="0 0 0" />
        <inertia ixx="0.001" ixy="0.0" ixz="0.0"
                 iyy="0.001" iyz="0.0" 
                 izz="0.001" />
       <!--
       <mass
         value="0.28581" />
           <inertia ixx="2.5512E-06"
        ixy="8.9939E-11"
        ixz="-1.2292E-08"
        iyy="2.5513E-06"
        iyz="8.169E-09"
        izz="8.0257E-09" />
      -->

     </inertial>

      <visual>
        <geometry>
          <mesh filename="package://adam_description/meshes/wheelright.STL"/>
        </geometry>
        <material
          name="rubber">
          <color
          rgba="0.79216 0.81961 0.93333 1" />
        </material>      
        <origin xyz="0 0 0" rpy="0 0 0"/>
      </visual>

    </link>
    
    
    <!--joint name="adam_caster_joint" type="fixed">
      <parent link="base_link"/>
      <child link="adam_caster_link"/>
      <origin xyz="-0.135 0.0 0.009" rpy="${-M_PI/2} 0 0"/>0.03
    </joint>
    <link name="adam_caster_link">
      <collision>
        <geometry>
          <cylinder length="0.0176" radius="0.017"/>
        </geometry>
        <origin rpy="0 0 0" xyz="0 0 0"/>
      </collision>
      <inertial>
        <mass value="0.01" />
        <origin xyz="0 0 0" />
        <inertia ixx="0.001" ixy="0.0" ixz="0.0"
                 iyy="0.001" iyz="0.0"
                 izz="0.001" />
      </inertial>
    </link-->
  
    <!-- ==================== adam simple sensors ====================-->  

    <joint name="gyro_joint" type="fixed">
      <axis xyz="0 1 0"/>
      <origin xyz="0.062 0.056 0.0202" rpy="0 0 0"/>
      <parent link="base_link"/>
      <child link="gyro_link"/>
    </joint>
    <link name="gyro_link">
      <inertial>
        <mass value="0.001"/>
        <origin xyz="0 0 0" rpy="0 0 0"/>
        <inertia ixx="0.0001" ixy="0" ixz="0" 
                 iyy="0.000001" iyz="0"
                 izz="0.0001"/>
      </inertial>
    </link>
    <joint name="cliff_sensor_right_joint" type="fixed">
      <origin xyz="0.228734 0.0013601 0.0214" rpy="0 ${-M_PI} ${-M_PI}" />
      <parent link="base_link"/>
      <child link="cliff_sensor_right_link" />
    </joint>
    <link name="cliff_sensor_right_link">

      <inertial>
        <mass value="0.0001" />
        <origin xyz="0 0 0" />
        <inertia ixx="0.0001" ixy="0.0" ixz="0.0"
                 iyy="0.0001" iyz="0.0" 
                 izz="0.0001" />
      </inertial>
    </link>

    <joint name="cliff_sensor_left_joint" type="fixed">
      <origin xyz="-0.228734 0.0013601 0.0214" rpy="0 ${-M_PI} 0" />    
      <parent link="base_link"/>
      <child link="cliff_sensor_left_link" />
    </joint>
    <link name="cliff_sensor_left_link">

      <inertial>
        <mass value="0.0001" />
        <origin xyz="0 0 0" />
        <inertia ixx="0.0001" ixy="0.0" ixz="0.0"
                 iyy="0.0001" iyz="0.0" 
                 izz="0.0001" />
      </inertial>
    </link>
    
    <joint name="cliff_sensor_front_joint" type="fixed">
      <origin xyz="0.0 0.1756 0.0214" rpy="0 ${-M_PI} ${-M_PI/2}" /> <!-- rpy="0 ${-M_PI} ${-M_PI/2}" -->
      <parent link="base_link"/>
      <child link="cliff_sensor_front_link" />
    </joint>
    <link name="cliff_sensor_front_link">

      <inertial>
        <mass value="0.0001" />
        <origin xyz="0 0 0" />
        <inertia ixx="0.0001" ixy="0.0" ixz="0.0"
                 iyy="0.0001" iyz="0.0" 
                 izz="0.0001" />
      </inertial>

      <visual>
        <geometry>
          <box size="0.006 0.001 0.002"/>
        </geometry>
        <material
          name="rubber">          
          <color
          rgba="0.79216 0.81961 0.93333 1" />
        </material>      
        <origin xyz="0 0 0" rpy="0 0 0"/>
      </visual>

    </link>
    
    <!--==================== Kobuki Gazebo simulation details ====================-->
    <kobuki_sim/>
    
  </xacro:macro>
</robot>
